Workbook

Sheet Summary
A1: ProgramOwnerController — STQAL test deliverables
A3: Test cases
A4: Technique | B4: Cases | C4: Pass | D4: Fail | E4: Blocked | F4: Not run
A5: BVA | B5: =COUNTIF(TestCases!$C$4:$C$63,A5) -> 20 | C5: =COUNTIFS(TestCases!$C$4:$C$63,A5,TestCases!$M$4:$M$63,"Pass") -> 17 | D5: =COUNTIFS(TestCases!$C$4:$C$63,A5,TestCases!$M$4:$M$63,"Fail") -> 3 | E5: =COUNTIFS(TestCases!$C$4:$C$63,A5,TestCases!$M$4:$M$63,"Blocked") -> 0 | F5: =COUNTIFS(TestCases!$C$4:$C$63,A5,TestCases!$M$4:$M$63,"Not run") -> 0
A6: ECT | B6: =COUNTIF(TestCases!$C$4:$C$63,A6) -> 20 | C6: =COUNTIFS(TestCases!$C$4:$C$63,A6,TestCases!$M$4:$M$63,"Pass") -> 12 | D6: =COUNTIFS(TestCases!$C$4:$C$63,A6,TestCases!$M$4:$M$63,"Fail") -> 8 | E6: =COUNTIFS(TestCases!$C$4:$C$63,A6,TestCases!$M$4:$M$63,"Blocked") -> 0 | F6: =COUNTIFS(TestCases!$C$4:$C$63,A6,TestCases!$M$4:$M$63,"Not run") -> 0
A7: Basis path | B7: =COUNTIF(TestCases!$C$4:$C$63,A7) -> 20 | C7: =COUNTIFS(TestCases!$C$4:$C$63,A7,TestCases!$M$4:$M$63,"Pass") -> 20 | D7: =COUNTIFS(TestCases!$C$4:$C$63,A7,TestCases!$M$4:$M$63,"Fail") -> 0 | E7: =COUNTIFS(TestCases!$C$4:$C$63,A7,TestCases!$M$4:$M$63,"Blocked") -> 0 | F7: =COUNTIFS(TestCases!$C$4:$C$63,A7,TestCases!$M$4:$M$63,"Not run") -> 0
A8: Total | B8: =SUM(B5:B7) -> 60 | C8: =SUM(C5:C7) -> 49 | D8: =SUM(D5:D7) -> 11 | E8: =SUM(E5:E7) -> 0 | F8: =SUM(F5:F7) -> 0
A10: Defects by severity
A11: Severity | B11: Count
A12: Critical | B12: =COUNTIF(Defects!$C$4:$C$35,A12) -> 1
A13: High | B13: =COUNTIF(Defects!$C$4:$C$35,A13) -> 9
A14: Medium | B14: =COUNTIF(Defects!$C$4:$C$35,A14) -> 7
A15: Low | B15: =COUNTIF(Defects!$C$4:$C$35,A15) -> 15
A16: Total | B16: =SUM(B12:B15) -> 32
A18: Basis path coverage
A19: Functions analysed | B19: =COUNTA(BasisPath!A5:A14) -> 10
A20: Independent paths (sum of V(G)) | B20: =BasisPath!E15 -> 59
A21: Functions where paths listed = V(G) | B21: =COUNTIF(BasisPath!G5:G14,"OK") -> 10
A23: How to use
A24: 1. Run: dotnet test Tests/AmarTools.Voting.Tests.csproj (all tests) | --filter "Category=Defect" (defect-confirming tests only).
A25: 2. TestCases results are filled from the latest runs (nondefect-output.txt, defect-output.txt, selenium-output.txt). Re-run and update the yellow cells if the code changes.
A26: 3. 'Predicted result' comes from reading the code, not from a test run. A predicted Fail that really fails becomes a confirmed defect: set Defects!L (Status) to Confirmed and M to Yes.
A27: 4. Test IDs of the form PO-0xx refer to the existing suite in ProgramOwnerControllerTests.cs; other names are methods in ProgramOwnerBoundaryDefectTests.cs or ProgramOwnerSeleniumFlowTests.cs.
A28: 5. Decision-point counts on BasisPath (blue) are the author's reading of the code; if the controller changes, update them and the path list.
A31: Test runs (from the output files)
A32: Run | B32: Total | C32: Passed | D32: Failed | E32: Skipped | F32: Evidence file
A33: Non-defect (Category!=Defect) | B33: 104 | C33: 104 | D33: 0 | E33: 0 | F33: nondefect-output.txt
A34: Defect (Category=Defect) | B34: 24 | C34: 6 | D34: 18 | E34: 0 | F34: defect-output.txt
A35: Selenium flows (subset of the two runs) | B35: 11 | C35: 11 | D35: 0 | E35: 0 | F35: selenium-output.txt
A36: Combined (non-defect + defect) | B36: =B33+B34 -> 128 | C36: =C33+C34 -> 110 | D36: =D33+D34 -> 18 | E36: =E33+E34 -> 0

Sheet TestCases
A1: ProgramOwnerController — test case design and execution (60 cases)
A3: TC ID | B3: Function / module | C3: Technique | D3: Priority | E3: Preconditions | F3: Test data | G3: Steps | H3: Expected result | I3: Predicted result (code reading) | J3: Automated test | K3: Defect ID | L3: Actual result | M3: Status | N3: Executed on | O3: Executed by
A4: BVA-01 | B4: Create/Edit (service) | C4: BVA | D4: High | E4: Logged in as owner | F4: Start +1h, End = Start + 299 s | G4: Submit create form | H4: Rejected: end must be at least 5 minutes after start | I4: Pass | J4: ProgramDuration_AtBoundary_IsEnforced(299,false) | L4: As expected; test passed. | M4: Pass | N4: 2026-10-09 | O4: Binoy Dev
A5: BVA-02 | B5: Create/Edit (service) | C5: BVA | D5: High | E5: Logged in as owner | F5: End = Start + 300 s | G5: Submit create form | H5: Accepted | I5: Pass | J5: ProgramDuration_AtBoundary_IsEnforced(300,true) | L5: As expected; test passed. | M5: Pass | N5: 2026-10-09 | O5: Binoy Dev
A6: BVA-03 | B6: Create/Edit (service) | C6: BVA | D6: Medium | E6: Logged in as owner | F6: End = Start + 301 s | G6: Submit create form | H6: Accepted | I6: Pass | J6: ProgramDuration_AtBoundary_IsEnforced(301,true) | L6: As expected; test passed. | M6: Pass | N6: 2026-10-09 | O6: Binoy Dev
A7: BVA-04 | B7: Create POST | C7: BVA | D7: Medium | E7: Model validation | F7: ProgramName length 2 | G7: Validate model | H7: Validation error (min 3) | I7: Pass | J7: ProgramName_LengthBoundary_MatchesModelRule(2,false) | L7: As expected; test passed. | M7: Pass | N7: 2026-10-09 | O7: Binoy Dev
A8: BVA-05 | B8: Create POST | C8: BVA | D8: Medium | E8: Model validation | F8: ProgramName length 3 | G8: Validate model | H8: Valid | I8: Pass | J8: ProgramName_LengthBoundary_MatchesModelRule(3,true) | L8: As expected; test passed. | M8: Pass | N8: 2026-10-09 | O8: Binoy Dev
A9: BVA-06 | B9: Create POST | C9: BVA | D9: Medium | E9: Model validation | F9: ProgramName length 200 | G9: Validate model | H9: Valid | I9: Pass | J9: ProgramName_LengthBoundary_MatchesModelRule(200,true) | L9: As expected; test passed. | M9: Pass | N9: 2026-10-09 | O9: Binoy Dev
A10: BVA-07 | B10: Create POST | C10: BVA | D10: Medium | E10: Model validation | F10: ProgramName length 201 | G10: Validate model | H10: Validation error (max 200) | I10: Pass | J10: ProgramName_LengthBoundary_MatchesModelRule(201,false) | L10: As expected; test passed. | M10: Pass | N10: 2026-10-09 | O10: Binoy Dev
A11: BVA-08 | B11: Create POST | C11: BVA | D11: Low | E11: Model validation | F11: Description 2000 / 2001 chars | G11: Validate model | H11: 2000 valid, 2001 error | I11: Pass | J11: ProgramDescription_LengthBoundary_MatchesModelRule | L11: As expected; test passed. | M11: Pass | N11: 2026-10-09 | O11: Binoy Dev
A12: BVA-09 | B12: AddCandidate | C12: BVA | D12: Low | E12: Upcoming program, owner | F12: name = 'A' (1 char), code C1 | G12: POST AddCandidate | H12: Rejected (min 2) | I12: Fail | J12: D07_AddCandidate_SingleCharacterName_IsRejected | K12: D07 | L12: Rejected after the fix; defect D07 is fixed and the regression test passes. | M12: Pass | N12: 2026-10-09 | O12: Binoy Dev
A13: BVA-10 | B13: AddCandidate | C13: BVA | D13: Medium | E13: Upcoming program, owner | F13: name 2 chars, code 1 char | G13: POST AddCandidate | H13: Saved | I13: Pass | J13: AddCandidate_NameAndCodeAtUpperAndLowerValidBounds_AreSaved(2,1) | L13: As expected; test passed. | M13: Pass | N13: 2026-10-09 | O13: Binoy Dev
A14: BVA-11 | B14: AddCandidate | C14: BVA | D14: Medium | E14: Upcoming program, owner | F14: name 150 chars, code 50 chars | G14: POST AddCandidate | H14: Saved | I14: Pass | J14: AddCandidate_NameAndCodeAtUpperAndLowerValidBounds_AreSaved(150,50) | L14: As expected; test passed. | M14: Pass | N14: 2026-10-09 | O14: Binoy Dev
A15: BVA-12 | B15: AddCandidate | C15: BVA | D15: Low | E15: Upcoming program, owner | F15: name 151 chars | G15: POST AddCandidate | H15: Rejected with message | I15: Fail | J15: D08_..._IsRejectedWithValidationMessage("name") | K15: D08 | L15: Rejected after the fix; defect D08 (name) is fixed and the regression test passes. | M15: Pass | N15: 2026-10-09 | O15: Binoy Dev
A16: BVA-13 | B16: AddCandidate | C16: BVA | D16: Low | E16: Upcoming program, owner | F16: code 51 chars | G16: POST AddCandidate | H16: Rejected with message | I16: Fail | J16: D08_..._IsRejectedWithValidationMessage("code") | K16: D08 | L16: Not rejected / incorrect behaviour; defect D08 confirmed (assertion failure). | M16: Fail | N16: 2026-10-09 | O16: Binoy Dev
A17: BVA-14 | B17: AddCandidate | C17: BVA | D17: Low | E17: Upcoming program, owner | F17: description 501 chars | G17: POST AddCandidate | H17: Rejected with message | I17: Fail | J17: D08_..._IsRejectedWithValidationMessage("description") | K17: D08 | L17: Not rejected / incorrect behaviour; defect D08 confirmed (assertion failure). | M17: Fail | N17: 2026-10-09 | O17: Binoy Dev
A18: BVA-15 | B18: AddCandidate | C18: BVA | D18: Low | E18: Upcoming program, owner | F18: imageUrl 501 chars | G18: POST AddCandidate | H18: Rejected with message | I18: Fail | J18: D08_..._IsRejectedWithValidationMessage("imageUrl") | K18: D08 | L18: Not rejected / incorrect behaviour; defect D08 confirmed (assertion failure). | M18: Fail | N18: 2026-10-09 | O18: Binoy Dev
A19: BVA-16 | B19: Edit GET | C19: BVA | D19: Medium | E19: No programs | F19: id = 0 | G19: GET /ProgramOwner/Edit/0 | H19: 404 NotFound | I19: Pass | J19: EditGet_NonExistingIdBoundaries_ReturnNotFound(0) | L19: As expected; test passed. | M19: Pass | N19: 2026-10-09 | O19: Binoy Dev
A20: BVA-17 | B20: Edit GET | C20: BVA | D20: Medium | E20: No programs | F20: id = -1 and int.MinValue | G20: GET Edit | H20: 404 NotFound | I20: Pass | J20: EditGet_NonExistingIdBoundaries_ReturnNotFound(-1, int.MinValue) | L20: As expected; test passed. | M20: Pass | N20: 2026-10-09 | O20: Binoy Dev
A21: BVA-18 | B21: Edit GET | C21: BVA | D21: Low | E21: No programs | F21: id = int.MaxValue | G21: GET Edit | H21: 404 NotFound | I21: Pass | J21: EditGet_NonExistingIdBoundaries_ReturnNotFound(int.MaxValue) | L21: As expected; test passed. | M21: Pass | N21: 2026-10-09 | O21: Binoy Dev
A22: BVA-19 | B22: ManageCandidates | C22: BVA | D22: Low | E22: Service returns null | F22: programId = 0, -1, int.MaxValue | G22: GET ManageCandidates | H22: 404 NotFound | I22: Pass | J22: ManageCandidates_NonExistingIdBoundaries_ReturnNotFound | L22: As expected; test passed. | M22: Pass | N22: 2026-10-09 | O22: Binoy Dev
A23: BVA-20 | B23: Delete | C23: BVA | D23: High | E23: Published program, owner | F23: EndTime = now-1 s (ended) / now+60 s (active) | G23: POST Delete | H23: Ended: deleted. Active: refused | I23: Pass | J23: Delete_PublishedProgramAroundEndTime_RespectsBoundary | L23: As expected; test passed. | M23: Pass | N23: 2026-10-09 | O23: Binoy Dev
A24: ECT-01 | B24: ManageCandidates | C24: ECT | D24: High | E24: Program owned by user | F24: Owner | G24: GET ManageCandidates | H24: View returned | I24: Pass | J24: PO-018 (existing) | L24: As expected; test passed. | M24: Pass | N24: 2026-10-09 | O24: Binoy Dev
A25: ECT-02 | B25: ManageCandidates | C25: ECT | D25: High | E25: Program owned by someone else | F25: Admin role | G25: GET ManageCandidates | H25: View returned | I25: Pass | J25: PO-020 (existing) | L25: As expected; test passed. | M25: Pass | N25: 2026-10-09 | O25: Binoy Dev
A26: ECT-03 | B26: ManageVoters | C26: ECT | D26: High | E26: Program owned by someone else | F26: Non-owner, non-admin | G26: GET ManageVoters | H26: Forbid | I26: Pass | J26: PO-049 (existing) | L26: As expected; test passed. | M26: Pass | N26: 2026-10-09 | O26: Binoy Dev
A27: ECT-04 | B27: MyPrograms | C27: ECT | D27: High | E27: No NameIdentifier claim | F27: Anonymous identity | G27: GET MyPrograms | H27: Unauthorized | I27: Pass | J27: PO-001 (existing) | L27: As expected; test passed. | M27: Pass | N27: 2026-10-09 | O27: Binoy Dev
A28: ECT-05 | B28: Results | C28: ECT | D28: Medium | E28: Program does not exist | F28: programId = 999 | G28: GET Results | H28: NotFound | I28: Pass | J28: PO-044 (existing) | L28: As expected; test passed. | M28: Pass | N28: 2026-10-09 | O28: Binoy Dev
A29: ECT-06 | B29: AddCandidate | C29: ECT | D29: Medium | E29: Owner | F29: imageUrl http://x.example/a.png | G29: POST AddCandidate | H29: Saved | I29: Pass | J29: PO-030 (existing) | L29: As expected; test passed. | M29: Pass | N29: 2026-10-09 | O29: Binoy Dev
A30: ECT-07 | B30: AddCandidate | C30: ECT | D30: Medium | E30: Owner | F30: imageUrl https://x.example/a.png | G30: POST AddCandidate | H30: Saved | I30: Pass | J30: PO-031 (existing) | L30: As expected; test passed. | M30: Pass | N30: 2026-10-09 | O30: Binoy Dev
A31: ECT-08 | B31: AddCandidate | C31: ECT | D31: Medium | E31: Owner | F31: imageUrl /images/a.png | G31: POST AddCandidate | H31: Saved | I31: Pass | J31: PO-032 (existing) | L31: As expected; test passed. | M31: Pass | N31: 2026-10-09 | O31: Binoy Dev
A32: ECT-09 | B32: AddCandidate | C32: ECT | D32: Medium | E32: Owner | F32: imageUrl //evil.example/a.png | G32: POST AddCandidate | H32: Rejected | I32: Fail | J32: D09_AddCandidate_ProtocolRelativeImageUrl_IsRejected | K32: D09 | L32: Rejected after the fix; defect D09 is fixed and the regression test passes. | M32: Pass | N32: 2026-10-09 | O32: Binoy Dev
A33: ECT-10 | B33: AddCandidate | C33: ECT | D33: High | E33: Owner | F33: imageUrl javascript:alert(1) | G33: POST AddCandidate | H33: Rejected | I33: Pass | J33: PO-034 (existing) | L33: As expected; test passed. | M33: Pass | N33: 2026-10-09 | O33: Binoy Dev
A34: ECT-11 | B34: AddCandidate | C34: ECT | D34: Medium | E34: Owner | F34: imageUrl ftp://x.example/a.png | G34: POST AddCandidate | H34: Rejected | I34: Pass | J34: PO-035 (existing) | L34: As expected; test passed. | M34: Pass | N34: 2026-10-09 | O34: Binoy Dev
A35: ECT-12 | B35: AddCandidate | C35: ECT | D35: Medium | E35: Candidate code 'A' exists | F35: code 'A' again | G35: POST AddCandidate | H35: Rejected as duplicate | I35: Pass | J35: PO-029 (existing) | L35: As expected; test passed. | M35: Pass | N35: 2026-10-09 | O35: Binoy Dev
A36: ECT-13 | B36: AddCandidate | C36: ECT | D36: Low | E36: Candidate code 'A' exists | F36: code 'a' | G36: POST AddCandidate | H36: Rejected as duplicate | I36: Fail | J36: D10_AddCandidate_CodeThatDiffersOnlyByCase_IsRejectedAsDuplicate | K36: D10 | L36: Not rejected / incorrect behaviour; defect D10 confirmed (assertion failure). | M36: Fail | N36: 2026-10-09 | O36: Binoy Dev
A37: ECT-14 | B37: AddCandidate | C37: ECT | D37: High | E37: Active published program | F37: Valid candidate | G37: POST AddCandidate | H37: Rejected: ballot frozen | I37: Fail | J37: D02_AddCandidate_WhileProgramIsActive_IsRejected | K37: D02 | L37: Not rejected / incorrect behaviour; defect D02 confirmed (assertion failure). | M37: Fail | N37: 2026-10-09 | O37: Binoy Dev
A38: ECT-15 | B38: AddCandidate | C38: ECT | D38: High | E38: Ended program | F38: Valid candidate | G38: POST AddCandidate | H38: Rejected | I38: Fail | J38: D02_AddCandidate_AfterProgramEnded_IsRejected | K38: D02 | L38: Not rejected / incorrect behaviour; defect D02 confirmed (assertion failure). | M38: Fail | N38: 2026-10-09 | O38: Binoy Dev
A39: ECT-16 | B39: DeleteCandidate | C39: ECT | D39: High | E39: Active published program | F39: Existing candidate | G39: POST DeleteCandidate | H39: Rejected | I39: Fail | J39: D02_DeleteCandidate_WhileProgramIsActive_IsRejected | K39: D02 | L39: Not rejected / incorrect behaviour; defect D02 confirmed (assertion failure). | M39: Fail | N39: 2026-10-09 | O39: Binoy Dev
A40: ECT-17 | B40: DeleteCandidate | C40: ECT | D40: High | E40: Candidate has a vote | F40: Existing candidate | G40: POST DeleteCandidate | H40: Rejected; votes preserved | I40: Fail | J40: D03_DeleteCandidate_WithRecordedVotes_IsRejected | K40: D03 | L40: Not rejected / incorrect behaviour; defect D03 confirmed (assertion failure). | M40: Fail | N40: 2026-10-09 | O40: Binoy Dev
A41: ECT-18 | B41: RegisterVoter | C41: ECT | D41: Medium | E41: Owner program | F41: email 'not-an-email' | G41: RegisterVoterByEmailAsync | H41: Rejected | I41: Fail | J41: D14_RegisterVoter_InvalidEmailFormat_IsRejected | K41: D14 | L41: Not rejected / incorrect behaviour; defect D14 confirmed (assertion failure). | M41: Fail | N41: 2026-10-09 | O41: Binoy Dev
...

Sheet BVA
A1: Boundary Value Analysis
A2: Seven-point boundary values (min-1, min, min+1, nominal, max-1, max, max+1) for every bounded input of ProgramOwnerController and the services it calls.
A4: Input | B4: Function | C4: Constraint (source) | D4: Below min | E4: Min | F4: Min+1 | G4: Nominal | H4: Max-1 | I4: Max | J4: Above max | K4: Expected behaviour | L4: Test cases
A5: Program duration (seconds) | B5: Create/Edit (service) | C5: End - Start >= 300 s (MinimumProgramDuration) | D5: 299 | E5: 300 | F5: 301 | G5: 3600 | H5: — | I5: — | J5: — | K5: <300 rejected; >=300 accepted | L5: BVA-01..03
A6: ProgramName length | B6: Create/Edit POST | C6: 3..200 (model StringLength) | D6: 2 | E6: 3 | F6: 4 | G6: 20 | H6: 199 | I6: 200 | J6: 201 | K6: Outside range -> validation error | L6: BVA-04..07
A7: Description length | B7: Create/Edit POST | C7: <= 2000 (model) | D7: — | E7: 0 | F7: 1 | G7: 200 | H7: 1999 | I7: 2000 | J7: 2001 | K7: 2001 -> validation error | L7: BVA-08
A8: Candidate name length | B8: AddCandidate | C8: 2..150 (model; NOT enforced in action) | D8: 1 | E8: 2 | F8: 3 | G8: 12 | H8: 149 | I8: 150 | J8: 151 | K8: Outside range rejected (defects D07, D08) | L8: BVA-09..12
A9: Candidate code length | B9: AddCandidate | C9: 1..50 (model; NOT enforced in action) | D9: 0 (blank) | E9: 1 | F9: 2 | G9: 6 | H9: 49 | I9: 50 | J9: 51 | K9: Outside range rejected (D08) | L9: BVA-10,11,13
A10: Candidate description length | B10: AddCandidate | C10: <= 500 | D10: — | E10: 0 | F10: 1 | G10: 80 | H10: 499 | I10: 500 | J10: 501 | K10: 501 rejected (D08) | L10: BVA-14
A11: Image URL length | B11: AddCandidate | C11: <= 500 | D11: — | E11: 1 | F11: 2 | G11: 40 | H11: 499 | I11: 500 | J11: 501 | K11: 501 rejected (D08) | L11: BVA-15
A12: Program / candidate / voter id | B12: Edit, ManageCandidates, Delete, … | C12: Positive existing id | D12: int.MinValue, -1, 0 | E12: 1 (existing) | F12: 2 | G12: — | H12: — | I12: — | J12: int.MaxValue | K12: Non-existing ids -> 404 | L12: BVA-16..19
A13: Election end time vs now (delete) | B13: Delete | C13: HasEnded = now >= EndTime | D13: EndTime = now+60 s | E13: — | F13: — | G13: — | H13: — | I13: — | J13: EndTime = now-1 s | K13: Active: refused; ended: deleted | L13: BVA-20
A14: Voter name length | B14: RegisterVoter (service) | C14: 2..150 (model; NOT enforced in service) | D14: 1 | E14: 2 | F14: 3 | G14: 12 | H14: 149 | I14: 150 | J14: 151 | K14: Outside range rejected (D29) | L14: D29 test
A15: Voter email length | B15: RegisterVoter (service) | C15: <= 200 and valid format | D15: 'a' (no @) | E15: a@b.co | F15: — | G15: name@example.com | H15: 199 | I15: 200 | J15: 201 | K15: Invalid/too long rejected (D14) | L15: ECT-18

Sheet ECT
A1: Equivalence Class Testing
A3: Input | B3: Class | C3: Description | D3: Valid / invalid | E3: Representative value | F3: Expected | G3: Test cases
A4: Caller identity | B4: EC1 | C4: Program owner | D4: Valid | E4: owner-1 on own program | F4: Action allowed | G4: ECT-01
A5: Caller identity | B5: EC2 | C5: Admin on another owner's program | D5: Valid | E5: admin-1 with Admin role | F5: Action allowed | G5: ECT-02, BP-12, BP-16, BP-18
A6: Caller identity | B6: EC3 | C6: Authenticated non-owner, non-admin | D6: Invalid | E6: owner-1 on owner-2's program | F6: Forbid | G6: ECT-03
A7: Caller identity | B7: EC4 | C7: No user id claim | D7: Invalid | E7: — | F7: Unauthorized | G7: ECT-04
A8: Resource id | B8: EC5 | C8: Program/candidate exists | D8: Valid | E8: 1 | F8: Proceeds to ownership check | G8: ECT-01
A9: Resource id | B9: EC6 | C9: Program/candidate missing | D9: Invalid | E9: 999 | F9: NotFound | G9: ECT-05
A10: Program state | B10: EC7 | C10: Draft / upcoming | D10: Valid for edits | E10: IsPublished=false, start in future | F10: Edits and deletes allowed | G10: BP-20
A11: Program state | B11: EC8 | C11: Active (started, not ended) | D11: Invalid for ballot changes | E11: Start -1h, End +1h, published | F11: Candidate add/delete and rescheduling must be rejected | G11: ECT-14, ECT-16, ECT-20, BP-19
A12: Program state | B12: EC9 | C12: Ended | D12: Invalid for changes | E12: End -1h | F12: Add candidate / register voter rejected; delete should keep data | G12: ECT-15, ECT-19, BVA-20
A13: Candidate name | B13: EC10 | C13: Valid length 2..150 | D13: Valid | E13: Alice Rahman | F13: Saved | G13: BVA-10, BVA-11
A14: Candidate name | B14: EC11 | C14: Blank / whitespace | D14: Invalid | E14: '', ' ', null | F14: Rejected | G14: BP-11 (PO-021..023)
... A33: Browser time zone offset | B33: EC30 | C33: Offset missing | D33: Invalid | E33: null | F33: Rejected | G33: TimeBehaviorTests

Sheet BasisPath
A1: Basis path testing — 10 functions
A2: V(G) = decision points + 1. A decision point is each if, each && / || operand, ternary and catch. 'Paths listed' must equal V(G).
A4: Function | B4: Source lines | C4: Decision predicates | D4: Decision points | E4: V(G) | F4: Paths listed | G4: Check
A5: MyPrograms | B5: 33-52 | C5: userId empty | D5: 1 | E5: =D5+1 -> 2 | F5: =COUNTIF($A$18:$A$76,A5) -> 2 | G5: =IF(E5=F5,"OK","CHECK") -> OK
A6: Create POST | B6: 69-94 | C6: !ModelState.IsValid; !success; errorMessage != null; model.IsPublished | D6: 4 | E6: =D6+1 -> 5 | F6: =COUNTIF($A$18:$A$76,A6) -> 5 | G6: =IF(E6=F6,"OK","CHECK") -> OK
A7: Edit POST | B7: 119-143 | C7: id != model.Id; !ModelState.IsValid; !success; errorMessage != null; model.IsPublished | D7: 5 | E7: =D7+1 -> 6 | F7: =COUNTIF($A$18:$A$76,A7) -> 6 | G7: =IF(E7=F7,"OK","CHECK") -> OK
A8: ManageCandidates GET | B8: 146-157 | C8: program is null; owner != current; !Admin | D8: 3 | E8: =D8+1 -> 4 | F8: =COUNTIF($A$18:$A$76,A8) -> 4 | G8: =IF(E8=F8,"OK","CHECK") -> OK
A9: AddCandidate | B9: 162-226 | C9: name blank; code blank; program null; owner != current; !Admin; codeExists; imageUrl present; TryCreate; http; https; !validUrl; !relativeOk; description blank; catch DbUpdateException | D9: 14 | E9: =D9+1 -> 15 | F9: =COUNTIF($A$18:$A$76,A9) -> 15 | G9: =IF(E9=F9,"OK","CHECK") -> OK
A10: DeleteCandidate | B10: 232-257 | C10: candidate null; program null; owner != current; !Admin; candidate.ProgramId != programId; catch DbUpdateException | D10: 6 | E10: =D10+1 -> 7 | F10: =COUNTIF($A$18:$A$76,A10) -> 7 | G10: =IF(E10=F10,"OK","CHECK") -> OK
A11: Results | B11: 260-276 | C11: program null; owner != current; !Admin | D11: 3 | E11: =D11+1 -> 4 | F11: =COUNTIF($A$18:$A$76,A11) -> 4 | G11: =IF(E11=F11,"OK","CHECK") -> OK
A12: ManageVoters | B12: 280-300 | C12: program null; owner != current; !Admin | D12: 3 | E12: =D12+1 -> 4 | F12: =COUNTIF($A$18:$A$76,A12) -> 4 | G12: =IF(E12=F12,"OK","CHECK") -> OK
A13: RegisterVoter POST | B13: 319-337 | C13: program null; owner != current; !Admin; !success | D13: 4 | E13: =D13+1 -> 5 | F13: =COUNTIF($A$18:$A$76,A13) -> 5 | G13: =IF(E13=F13,"OK","CHECK") -> OK
A14: Delete | B14: 362-389 | C14: program null; owner != current; !Admin; IsPublished; !HasEnded; catch DbUpdateException | D14: 6 | E14: =D14+1 -> 7 | F14: =COUNTIF($A$18:$A$76,A14) -> 7 | G14: =IF(E14=F14,"OK","CHECK") -> OK
A15: Total | D15: =SUM(D5:D14) -> 49 | E15: =SUM(E5:E14) -> 59 | F15: =SUM(F5:F14) -> 59
A17: Function | B17: Path | C17: Condition path | D17: Expected outcome | E17: Test case(s)
A18: MyPrograms | B18: P1 | C18: userId empty | D18: Unauthorized | E18: BP-01
A19: MyPrograms | B19: P2 | C19: userId present | D19: View(programs of owner) | E19: BP-02
A20: Create POST | B20: P1 | C20: ModelState invalid | D20: Form, ValuesAreUtc=false | E20: BP-03
A21: Create POST | B21: P2 | C21: valid; service fails; message present | D21: Form + model error | E21: BP-04
A22: Create POST | B22: P3 | C22: valid; service fails; message null | D22: Form, no model error | E22: BP-05
A23: Create POST | B23: P4 | C23: valid; success; not published | D23: Redirect MyPrograms | E23: BP-06
A24: Create POST | B24: P5 | C24: valid; success; published | D24: PublishedLink + redirect | E24: BP-07
A25: Edit POST | B25: P1 | C25: id != model.Id | D25: NotFound | E25: BP-08
A26: Edit POST | B26: P2 | C26: ModelState invalid | D26: Form | E26: PO-014
A27: Edit POST | B27: P3 | C27: service fails; message present | D27: Form + model error | E27: PO-015
A28: Edit POST | B28: P4 | C28: service fails; message null | D28: Form, no model error | E28: BP-09
... A76: Delete | B76: P7 | C76: DbUpdateException | D76: Error + redirect | E76: needs fault-injection test (add)

Sheet Defects
A1: Defect reports (32) — D01–D14 tests run by the author; the rest are from code inspection. Confirm each and record the actual result
A3: Defect ID | B3: Title | C3: Severity | D3: Priority | E3: Location | F3: Preconditions | G3: Steps to reproduce | H3: Expected result | I3: Actual result (from code reading) | J3: Test / evidence | K3: Suggested fix | L3: Status | M3: Confirmed by test run?
A4: D01 | B4: Edit allows rescheduling/reopening a program after voting started or ended | C4: High | D4: P1 | E4: VotingService.ValidateAndUpdateProgramAsync (called from ProgramOwnerController.Edit POST, line ~119) | F4: Published program already started (or ended); logged in as owner | G4: 1) Open Edit for a started program. 2) Move Start/End into the future (or extend End of an ended program). 3) Save. | H4: Update rejected once voting has started; ended elections cannot be reopened. | I4: Update succeeds. No lifecycle check exists in the service. | J4: D01_Edit_StartedProgram_CannotBeRescheduledIntoTheFuture, D01_Edit_EndedProgram_CannotBeReopened | K4: Reject changes to StartTime/EndTime/IsPublished when program HasStarted (allow only name/description). | L4: Confirmed | M4: Yes
A5: D02 | B5: Candidates can be added or deleted while the election is active or after it ended | C5: High | D5: P1 | E5: ProgramOwnerController.AddCandidate (line ~162), DeleteCandidate (line ~232) | F5: Published program that is active (or ended) | G5: 1) Open ManageCandidates for an active program. 2) Add a candidate / delete one. | H5: Rejected with an error: the ballot is frozen once voting starts. | I5: Candidate is added/deleted. No state check in either action. | J5: D02_AddCandidate_WhileProgramIsActive_IsRejected, D02_AddCandidate_AfterProgramEnded_IsRejected, D02_DeleteCandidate_WhileProgramIsActive_IsRejected | K5: Add `if (program.HasStarted) { TempData["Error"]=...; redirect }` in both actions. | L5: Confirmed | M5: Yes
A6: D03 | B6: Deleting a candidate that has votes silently deletes those votes (FK cascade) | C6: High | D6: P1 | E6: ProgramOwnerController.DeleteCandidate; Migrations/20260418054953_Initialcreate.cs (FK_Votes_Candidates_CandidateId = Cascade) | F6: Candidate has at least one vote | G6: 1) Delete a candidate who received votes. | H6: Delete refused (or votes preserved); tallies and hash chain unchanged. | I6: Candidate and its votes are removed; vote totals drop and the blockchain chain no longer validates. | J6: D03_DeleteCandidate_WithRecordedVotes_IsRejected | K6: Check for votes before delete; change FK to Restrict via migration. | L6: Confirmed | M6: Yes
A7: D04 | B7: Removing a voter who already voted deletes their vote (FK cascade) | C7: High | D7: P1 | E7: VotingService.RemoveVoterAsync; FK_Votes_Voters_VoterId = Cascade | F7: Voter has HasVoted = true | G7: 1) Open ManageVoters. 2) Remove a voter who has voted. | H7: Removal refused for voters who have voted. | I7: Voter and the vote row are removed; chain breaks. No HasVoted check. | J7: D04_RemoveVoter_VoterWhoAlreadyVoted_IsRejected | K7: Return error when voter.HasVoted; change FK to Restrict. | L7: Confirmed | M7: Yes
A8: D05 | B8: A program with recorded votes can be hard-deleted as soon as it ends | C8: Medium | D8: P2 | E8: ProgramOwnerController.Delete (line ~362); cascade FK on Votes/BlockchainVotes; VotingDbContext Owner OnDelete Cascade | F8: Ended published program with votes | G8: 1) Wait for the end time. 2) Click Delete on MyPrograms. | H8: Results and audit trail preserved (soft delete / archive). | I8: Program, votes and blocks are permanently removed. Deleting an Identity user also cascades to their programs. | J8: D05_Delete_EndedProgramWithVotes_IsNotHardDeleted | K8: Soft-delete (IsDeleted flag) or block deletion when votes exist. | L8: Confirmed | M8: Yes
A9: D06 | B9: After a duration-validation failure the form re-renders with shifted times | C9: Low | D9: P3 | E9: VotingService.ValidateProgramAsync (sets ValuesAreUtc = true before assigning StartTime/EndTime) | F9: Browser time zone is not UTC | G9: 1) Create program with End < Start + 5 min. 2) Submit. 3) Look at Start/End on the re-rendered form. | H9: Times shown exactly as typed. | I9: ValuesAreUtc is true while the model still holds local values, so the JS converts them again and the times shift by the UTC offset; every retry shifts again. Reachable only when the page's client-side 5-minute check (a JavaScript alert) is bypassed, so the browser test cannot reach it; the unit test confirms it. | J9: D06_DurationFailure_DoesNotLeaveLocalTimesFlaggedAsUtc; Selenium S03 | K9: Set ValuesAreUtc only after StartTime/EndTime have been assigned UTC values. | L9: Confirmed | M9: Yes
A10: D07 | B10: Candidate name of 1 character is accepted (model requires 2..150) | C10: Low | D10: P3 | E10: ProgramOwnerController.AddCandidate (parameters bypass model validation) | F10: Any program | G10: 1) POST name = 'A' with a valid code. | H10: Rejected with 'Name must be between 2 and 150 characters'. | I10: Before the fix a 1-character name was saved. Now rejected. | J10: D07_AddCandidate_SingleCharacterName_IsRejected; Selenium S08 | K10: Bind to Candidate model with ModelState validation, or check lengths explicitly. | L10: Fixed | M10: Yes
A11: D08 | B11: No server-side maximum-length checks for candidate fields | C11: Low | D11: P3 | E11: ProgramOwnerController.AddCandidate | F11: Crafted POST (browser maxlength can be bypassed) | G11: 1) POST name 151 / code 51 / description 501 / imageUrl 501 characters. | H11: Specific validation message; nothing saved. | I11: Database throws DbUpdateException; user sees only 'Candidate could not be saved'. | J11: D08_AddCandidate_FieldOverMaxLength_IsRejectedWithValidationMessage (4 cases) | K11: Validate lengths before SaveChanges. | L11: Partly fixed | M11: Yes
A12: D09 | B12: Protocol-relative image URL (//host/img.png) is accepted | C12: Low | D12: P3 | E12: ProgramOwnerController.AddCandidate (`imageUrl.StartsWith('/')`) | F12: Any program | G12: 1) Add candidate with imageUrl = //evil.example/photo.png. | H12: Rejected as not a valid image URL. | I12: Before the fix a protocol-relative URL was saved and browsers loaded the image from the external host. Now rejected. | J12: D09_AddCandidate_ProtocolRelativeImageUrl_IsRejected; Selenium S07 | K12: Require StartsWith('/') && !StartsWith("//") && !StartsWith("/\\"). | L12: Fixed | M12: Yes
A13: D10 | B13: Candidate-code uniqueness is case-sensitive | C13: Low | D13: P3 | E13: ProgramOwnerController.AddCandidate; unique index on (ProgramId, CandidateCode) | F13: Candidate with code 'A' exists | G13: 1) Add another candidate with code 'a'. | H13: Rejected as duplicate. | I13: Saved: 'A' and 'a' coexist. | J13: D10_AddCandidate_CodeThatDiffersOnlyByCase_IsRejectedAsDuplicate | K13: Compare with ToLower()/ordinal-ignore-case and normalise on save. | L13: Confirmed | M13: Yes
A14: D11 | B14: Inconsistent NotFound/Forbid responses reveal which IDs exist | C14: Low | D14: P3 | E14: ProgramOwnerController.DeleteCandidate, RemoveVoter | F14: Logged in as a different owner | G14: 1) DeleteCandidate for a candidate of someone else's program. 2) DeleteCandidate for a non-existent id. 3) RemoveVoter for a missing program. | H14: Same response for 'missing' and 'not yours'. | I14: 403 vs 404 differ, so IDs can be enumerated; RemoveVoter returns 403 for a missing program while other actions return 404. | J14: D11_DeleteCandidate_ExistingAndMissingCandidateOfOtherProgram_BehaveTheSame; D11_RemoveVoter_MissingProgram_ReturnsNotFoundLikeTheOtherActions | K14: Return NotFound for both cases. (Note: existing test PO-056 asserts the current Forbid behaviour.) | L14: Confirmed | M14: Yes
... A35: D32 | B35: Verification fields are never set or read (Vote.IsVerified, Vote.VerifiedAt, Vote.BlockchainReference, Voter.IsVerified, Voter.VerifiedAt) | C35: Low | D35: P3 | E35: Models/Vote.cs lines 50-55; Models/Voter.cs lines 60-61 | F35: Any recorded vote | G35: 1) Cast a vote. 2) Inspect the Votes and Voters rows. | H35: Votes reference their blockchain block and verification state is meaningful. | I35: The columns always keep their defaults (false / null), so a vote row cannot be tied to its block and nothing reports verification. | J35: Code search: no assignment or read outside the model classes | K35: Populate BlockchainReference when the block is created, or remove the unused columns. | L35: Open | M35: Not yet

Sheet Selenium
A1: Selenium flow tests (ProgramOwnerSeleniumFlowTests) — run against http://localhost:5256, evidence: selenium-output.txt
A3: Test | B3: Scenario | C3: Result | D3: Related defect
A4: Dashboard_IsShownAfterLogin | B4: Login and dashboard | C4: Pass
A5: CreateProgram_ValidInput_AppearsOnDashboard | B5: Create a program through the form | C5: Pass
A6: CreateProgram_DurationUnderFiveMinutes_KeepsTheTimesTheUserTyped | B6: Client-side 5-minute alert; typed times stay in the form | C6: Pass | D6: D06 (server side is covered by the unit test)
A7: AddCandidate_ValidInput_ShowsSuccess | B7: Add candidate | C7: Pass
A8: AddCandidate_DuplicateCode_ShowsError | B8: Duplicate candidate code | C8: Pass
A9: AddCandidate_JavascriptImageUrl_IsRejected | B9: javascript: image URL rejected | C9: Pass
A10: AddCandidate_ProtocolRelativeImageUrl_IsRejected | B10: //host image URL rejected | C10: Pass | D10: D09 regression
A11: AddCandidate_SingleCharacterName_IsRejected | B11: 1-character name rejected | C11: Pass | D11: D07 regression
A12: RegisterVoter_ValidInput_ShowsSuccess | B12: Register voter | C12: Pass
A13: RegisterVoter_DuplicateEmail_ShowsError | B13: Duplicate voter email | C13: Pass
A14: DeleteProgram_Unpublished_RemovesItFromTheDashboard | B14: Delete unpublished program (confirm dialog) | C14: Pass
